Workbook

Sheet 5º Ano - CONSOLIDADO
G6: COLEÇÃO PREPARA BRASIL
G9: ANÁLISE DE DESEMPENHO - SIMULADO 4
G12: Unidade de Ensino: 1. EMEB BENTO ELOI GARCIA
A16: 5º ANO - CONSOLIDADO
A18: NÚMERO DE ALUNOS MATRICULADOS: | F18: =C40 -> 169
A19: NÚMERO DE PRESENTES | F19: =D40 -> 163
A20: NÚMERO DE ALUNOS AUSENTES | F20: =E40 -> 6
A21: NÚMERO DE ACD | F21: =F40 -> 8
A23: GUIA DE CORREÇÃO - PRODUÇÃO TEXTUAL
G25: DESEMPENHO POR ITEM
A26: Nº | B26: TURMA | C26: Nº DE ALUNOS MATRICULADOS | D26: Nº DE ALUNOS PRESENTES | E26: Nº DE ALUNOS AUSENTES | F26: Nº DE ACD | G26: LINGUAGENS | AB26: MATEMÁTICA
G27: Questão 01 | H27: Questão 02 | I27: Questão 03 | J27: Questão 04 | K27: Questão 05 | L27: Questão 06 | M27: Questão 07 | N27: Questão 08 | O27: Questão 09 | P27: Questão 10 | Q27: Questão 11 | R27: Questão 12 | S27: Questão 13 | T27: Questão 14 | U27: Questão 15 | V27: Questão 16 | W27: Questão 17 | X27: Questão 18 | Y27: Questão 19 | Z27: Questão 20 | AA27: Questão 21 | AB27: Questão 01 | AC27: Questão 02 | AD27: Questão 03 | AE27: Questão 04 | AF27: Questão 05 | AG27: Questão 06 | AH27: Questão 07 | AI27: Questão 08 | AJ27: Questão 09 | AK27: Questão 10 | AL27: Questão 11 | AM27: Questão 12 | AN27: Questão 13 | AO27: Questão 14 | AP27: Questão 15 | AQ27: Questão 16 | AR27: Questão 17 | AS27: Questão 18 | AT27: Questão 19 | AU27: Questão 20 | AV27: Questão 21 | AW27: Questão 22
G29: C | H29: C | I29: C | J29: B | K29: B | L29: D | M29: B | N29: B | O29: A | P29: B | Q29: C | R29: C | S29: A | T29: B | U29: D | V29: A | W29: A | X29: A | Y29: C | Z29: D | AA29: B | AB29: A | AC29: D | AD29: C | AE29: D | AF29: C | AG29: C | AH29: B | AI29: A | AJ29: D | AK29: A | AL29: C | AM29: B | AN29: D | AO29: B | AP29: C | AQ29: A | AR29: B | AS29: D | AT29: A | AU29: C | AV29: C | AW29: B
A30: 1 | B30: 5º ANO - 501 | C30: {='5º Ano - 501'!$C$18} -> 29 | D30: {='5º Ano - 501'!$C$19} -> 28 | E30: {='5º Ano - 501'!$C$20} -> 1 | F30: {='5º Ano - 501'!$C$21} -> 1 | G30: {='5º Ano - 501'!$D$70:AT$70} -> 9 | H30: 11 | I30: 10 | J30: 3 | K30: 14 | L30: 5 | M30: 4 | N30: 6 | O30: 1 | P30: 13 | Q30: 1 | R30: 2 | S30: 3 | T30: 1 | U30: 13 | V30: 1 | W30: 3 | X30: 1 | Y30: 0 | Z30: 0 | AA30: 15 | AB30: 1 | AC30: 1 | AD30: 24 | AE30: 26 | AF30: 2 | AG30: 2 | AH30: 20 | AI30: 1 | AJ30: 2 | AK30: 2 | AL30: 1 | AM30: 0 | AN30: 2 | AO30: 1 | AP30: 0 | AQ30: 3 | AR30: 1 | AS30: 1 | AT30: 12 | AU30: 4 | AV30: 1 | AW30: 4
A31: 2 | B31: 5º ANO - 502 | C31: {='5º Ano - 502'!$C$18} -> 29 | D31: {='5º Ano - 502'!$C$19} -> 29 | E31: {='5º Ano - 502'!$C$20} -> 0 | F31: {='5º Ano - 502'!$C$21} -> 1 | G31: {='5º Ano - 502'!$D$70:AT$70} -> 4 | H31: 4 | I31: 14 | J31: 8 | K31: 19 | L31: 10 | M31: 2 | N31: 8 | O31: 0 | P31: 15 | Q31: 3 | R31: 0 | S31: 0 | T31: 3 | U31: 0 | V31: 2 | W31: 3 | X31: 1 | Y31: 0 | Z31: 1 | AA31: 21 | AB31: 1 | AC31: 1 | AD31: 27 | AE31: 25 | AF31: 4 | AG31: 6 | AH31: 21 | AI31: 1 | AJ31: 3 | AK31: 7 | AL31: 0 | AM31: 1 | AN31: 1 | AO31: 1 | AP31: 2 | AQ31: 2 | AR31: 3 | AS31: 2 | AT31: 2 | AU31: 3 | AV31: 3 | AW31: 8
A32: 3 | B32: 5º ANO - 503 | C32: {='5º Ano - 503'!$C$18} -> 29 | D32: {='5º Ano - 503'!$C$19} -> 27 | E32: {='5º Ano - 503'!$C$20} -> 2 | F32: {='5º Ano - 503'!$C$21} -> 2 | G32: {='5º Ano - 503'!$D$70:AT$70} -> 2 | H32: 21 | I32: 0 | J32: 2 | K32: 24 | L32: 19 | M32: 1 | N32: 1 | O32: 2 | P32: 22 | Q32: 1 | R32: 22 | S32: 2 | T32: 1 | U32: 19 | V32: 0 | W32: 1 | X32: 5 | Y32: 1 | Z32: 1 | AA32: 21 | AB32: 0 | AC32: 0 | AD32: 25 | AE32: 24 | AF32: 1 | AG32: 1 | AH32: 21 | AI32: 0 | AJ32: 1 | AK32: 1 | AL32: 2 | AM32: 0 | AN32: 1 | AO32: 0 | AP32: 0 | AQ32: 2 | AR32: 2 | AS32: 1 | AT32: 21 | AU32: 3 | AV32: 1 | AW32: 4
A33: 4 | B33: 5º ANO - 504 | C33: {='5º Ano - 504'!$C$18} -> 30 | D33: {='5º Ano - 504'!$C$19} -> 27 | E33: {='5º Ano - 504'!$C$20} -> 3 | F33: {='5º Ano - 504'!$C$21} -> 2 | G33: {='5º Ano - 504'!$D$70:AT$70} -> 4 | H33: 6 | I33: 3 | J33: 5 | K33: 14 | L33: 10 | M33: 3 | N33: 3 | O33: 2 | P33: 7 | Q33: 1 | R33: 5 | S33: 6 | T33: 7 | U33: 9 | V33: 3 | W33: 2 | X33: 2 | Y33: 3 | Z33: 4 | AA33: 9 | AB33: 10 | AC33: 3 | AD33: 15 | AE33: 6 | AF33: 5 | AG33: 11 | AH33: 8 | AI33: 3 | AJ33: 3 | AK33: 7 | AL33: 2 | AM33: 0 | AN33: 4 | AO33: 1 | AP33: 2 | AQ33: 2 | AR33: 2 | AS33: 5 | AT33: 3 | AU33: 8 | AV33: 6 | AW33: 8
A34: 5 | B34: 5º ANO - 505 | C34: {='5º Ano - 505'!$C$18} -> 29 | D34: {='5º Ano - 505'!$C$19} -> 29 | E34: {='5º Ano - 505'!$C$20} -> 0 | F34: {='5º Ano - 505'!$C$21} -> 2 | G34: {='5º Ano - 505'!$D$70:AT$70} -> 4 | H34: 12 | I34: 12 | J34: 7 | K34: 9 | L34: 2 | M34: 9 | N34: 4 | O34: 1 | P34: 10 | Q34: 2 | R34: 20 | S34: 0 | T34: 2 | U34: 8 | V34: 1 | W34: 10 | X34: 2 | Y34: 0 | Z34: 3 | AA34: 22 | AB34: 0 | AC34: 1 | AD34: 25 | AE34: 22 | AF34: 3 | AG34: 4 | AH34: 23 | AI34: 0 | AJ34: 4 | AK34: 7 | AL34: 4 | AM34: 1 | AN34: 0 | AO34: 3 | AP34: 0 | AQ34: 2 | AR34: 7 | AS34: 3 | AT34: 13 | AU34: 7 | AV34: 1 | AW34: 6
A35: 5 | B35: 5º ANO - 506 | C35: {='5º Ano - 506'!$C$18} -> 23 | D35: {='5º Ano - 506'!$C$19} -> 23 | E35: {='5º Ano - 506'!$C$20} -> 0 | F35: {='5º Ano - 506'!$C$21} -> 0 | G35: {='5º Ano - 506'!$D$70:AT$70} -> 1 | H35: 21 | I35: 3 | J35: 1 | K35: 19 | L35: 1 | M35: 0 | N35: 0 | O35: 1 | P35: 20 | Q35: 1 | R35: 19 | S35: 2 | T35: 0 | U35: 2 | V35: 1 | W35: 0 | X35: 3 | Y35: 0 | Z35: 0 | AA35: 19 | AB35: 2 | AC35: 0 | AD35: 21 | AE35: 19 | AF35: 2 | AG35: 0 | AH35: 18 | AI35: 3 | AJ35: 3 | AK35: 2 | AL35: 2 | AM35: 1 | AN35: 2 | AO35: 2 | AP35: 1 | AQ35: 1 | AR35: 3 | AS35: 1 | AT35: 17 | AU35: 2 | AV35: 1 | AW35: 1
A36: 5
A37: 5
A38: 5
A39: 5
C40: =SUM(C30:C39) -> 169 | D40: =SUM(D30:D39) -> 163 | E40: =SUM(E30:E39) -> 6 | F40: =SUM(F30:F39) -> 8 | G40: =SUM(G30:G39) -> 24 | H40: =SUM(H30:H39) -> 75 | I40: =SUM(I30:I39) -> 42 | J40: =SUM(J30:J39) -> 26 | ... AW40: =SUM(AW30:AW39) -> 31
G42: DESEMPENHO POR HABILIDADE
G43: QUESTÃO | I43: Nº. A | J43: % | K43: HABILIDADE
G45: LINGUAGENS | H45: 1 | I45: =G40 -> 24 | J45: =SUM(I45/F$18*100) -> 14.201183 | K45: Eixo do conhecimento: Análise linguística/semiótica. Eixo cognitivo: Reconhecer – Identificar os mecanismos de progressão textual.
H46: 2 | I46: =H40 -> 75 | J46: =SUM(I46/F$18*100) -> 44.378698 | K46: Eixo do conhecimento: Leitura. Eixo cognitivo: Reconhecer – Identificar a ideia central do texto.
H47: 3 | I47: =I40 -> 42 | J47: =SUM(I47/F$18*100) -> 24.852071 | K47: Eixo do conhecimento: Leitura. Eixo cognitivo: Analisar – Analisar elementos constitutivos de gêneros textuais diversos.
H48: 4 | I48: =J40 -> 26 | J48: =SUM(I48/F$18*100) -> 15.384615 | K48: Eixo do conhecimento: Leitura. Eixo cognitivo: Reconhecer – Identificar a ideia central do texto.
H49: 5 | I49: =K40 -> 99 | J49: =SUM(I49/F$18*100) -> 58.579882 | K49: Eixo do conhecimento: Leitura. Eixo cognitivo: Reconhecer – Localizar informação explícita.
H50: 6 | I50: =L40 -> 47 | J50: =SUM(I50/F$18*100) -> 27.810651 | K50: Eixo do conhecimento: Leitura. Eixo cognitivo: Reconhecer – Identificar a ideia central do texto.
H51: 7 | I51: =M40 -> 19 | J51: =SUM(I51/F$18*100) -> 11.242604 | K51: Eixo do conhecimento: Leitura. Eixo cognitivo: Reconhecer – Reconhecer diferentes gêneros textuais.
H52: 8 | I52: =N40 -> 22 | J52: =SUM(I52/F$18*100) -> 13.017751 | K52: Eixo do conhecimento: Leitura. Eixo cognitivo: Analisar – Inferir informações implícitas em textos.
H53: 9 | I53: =O40 -> 7 | J53: =SUM(I53/F$18*100) -> 4.1420118 | K53: Eixo do conhecimento: Leitura. Eixo cognitivo: Reconhecer – Identificar as marcas de organização de textos dramáticos.
H54: 10 | I54: =P40 -> 87 | J54: =SUM(I54/F$18*100) -> 51.47929 | K54: Eixo do conhecimento: Leitura. Eixo cognitivo: Analisar – Analisar elementos constitutivos de gêneros textuais diversos.
H55: 11 | I55: =Q40 -> 9 | J55: =SUM(I55/F$18*100) -> 5.3254438 | K55: Eixo do conhecimento: Leitura. Eixo cognitivo: Reconhecer – Identificar as marcas de organização de um texto dramático.
H56: 12 | I56: =R40 -> 68 | J56: =SUM(I56/F$18*100) -> 40.236686 | K56: Eixo do conhecimento: Arte. Eixo cognitivo: Analisar – Analisar expressões do teatro e da dança na vida cotidiana
H57: 13 | I57: =S40 -> 13 | J57: =SUM(I57/F$18*100) -> 7.6923077 | K57: Eixo do conhecimento: Leitura. Eixo cognitivo: Reconhecer – Identificar as marcas de organização de um texto dramático.
H58: 14 | I58: =T40 -> 14 | J58: =SUM(I58/F$18*100) -> 8.2840237 | K58: Eixo do conhecimento: Leitura. Eixo cognitivo: Reconhecer – Identificar as marcas de organização de um texto dramático
...

Sheet 9º Ano - CONSOLIDADO
G6: COLEÇÃO PREPARA BRASIL
G9: ANÁLISE DE DESEMPENHO - SIMULADO 4
G12: Unidade de Ensino: 1. EMEB BENTO ELOI GARCIA
A15: 9º ANO - CONSOLIDADO
A17: NÚMERO DE ALUNOS MATRICULADOS: | F17: =C40 -> 110
A18: NÚMERO DE PRESENTES | F18: =D40 -> 93
A19: NÚMERO DE ALUNOS AUSENTES | F19: =E40 -> 17
A20: NÚMERO DE ACD | F20: =F40 -> 1
A22: GUIA DE CORREÇÃO - PRODUÇÃO TEXTUAL
G25: DESEMPENHO POR ITEM
A26: Nº | B26: TURMA | C26: Nº DE ALUNOS MATRICULADOS | D26: Nº DE ALUNOS PRESENTES | E26: Nº DE ALUNOS AUSENTES | F26: Nº DE ACD | G26: LINGUAGENS | AF26: MATEMÁTICA
G27: Questão 01 | H27: Questão 02 | I27: Questão 03 | J27: Questão 04 | K27: Questão 05 | L27: Questão 06 | M27: Questão 07 | N27: Questão 08 | O27: Questão 09 | P27: Questão 10 | Q27: Questão 11 | R27: Questão 12 | S27: Questão 13 | T27: Questão 14 | U27: Questão 15 | V27: Questão 16 | W27: Questão 17 | X27: Questão 18 | Y27: Questão 19 | Z27: Questão 20 | AA27: Questão 21 | AB27: Questão 22 | AC27: Questão 23 | AD27: Questão 24 | AE27: Questão 25 | AF27: Questão 01 | AG27: Questão 02 | AH27: Questão 03 | AI27: Questão 04 | AJ27: Questão 05 | AK27: Questão 06 | AL27: Questão 07 | AM27: Questão 08 | AN27: Questão 09 | AO27: Questão 10 | AP27: Questão 11 | AQ27: Questão 12 | AR27: Questão 13 | AS27: Questão 14 | AT27: Questão 15 | AU27: Questão 16 | AV27: Questão 17 | AW27: Questão 18 | AX27: Questão 19 | AY27: Questão 20 | AZ27: Questão 21 | BA27: Questão 22 | BB27: Questão 23 | BC27: Questão 24 | BD27: Questão 25 | BE27: Questão 26
G29: A | H29: A | I29: C | J29: B | K29: D | L29: B | M29: C | N29: A | O29: D | P29: B | Q29: A | R29: B | S29: B | T29: A | U29: A | V29: C | W29: B | X29: A | Y29: B | Z29: C | AA29: A | AB29: A | AC29: B | AD29: B | AE29: B | AF29: C | AG29: B | AH29: B | AI29: C | AJ29: C | AK29: C | AL29: D | AM29: B | AN29: D | AO29: A | AP29: C | AQ29: B | AR29: D | AS29: B | AT29: C | AU29: A | AV29: B | AW29: C | AX29: D | AY29: D | AZ29: C | BA29: B | BB29: B | BC29: D | BD29: C | BE29: D
A30: 1 | B30: 9º ANO - 901 | C30: {='9º Ano - 901'!$C$17} -> 30 | D30: {='9º Ano - 901'!$C$18} -> 26 | E30: {='9º Ano - 901'!$C$19} -> 4 | F30: {='9º Ano - 901'!$C$20} -> 0 | G30: {='9º Ano - 901'!$D$70:$BB$70} -> 2 | H30: 8 | I30: 1 | J30: 2 | K30: 7 | L30: 7 | M30: 7 | N30: 4 | O30: 10 | P30: 8 | Q30: 1 | R30: 3 | S30: 5 | T30: 2 | U30: 2 | V30: 3 | W30: 17 | X30: 5 | Y30: 7 | Z30: 7 | AA30: 6 | AB30: 16 | AC30: 2 | AD30: 5 | AE30: 7 | AF30: 4 | AG30: 11 | AH30: 2 | AI30: 8 | AJ30: 9 | AK30: 3 | AL30: 10 | AM30: 9 | AN30: 4 | AO30: 6 | AP30: 8 | AQ30: 7 | AR30: 9 | AS30: 6 | AT30: 7 | AU30: 10 | AV30: 10 | AW30: 2 | AX30: 6 | AY30: 2 | AZ30: 10 | BA30: 6 | BB30: 4 | BC30: 7 | BD30: 8 | BE30: 3
A31: 2 | B31: 9º ANO - 902 | C31: {='9º Ano - 902'!$C$17} -> 31 | D31: {='9º Ano - 902'!$C$18} -> 25 | E31: {='9º Ano - 902'!$C$19} -> 6 | F31: {='9º Ano - 902'!$C$20} -> 0 | G31: {='9º Ano - 902'!$D$70:$BB$70} -> 5 | H31: 4 | I31: 2 | J31: 5 | K31: 5 | L31: 2 | M31: 4 | N31: 2 | O31: 11 | P31: 5 | Q31: 6 | R31: 3 | S31: 3 | T31: 7 | U31: 5 | V31: 1 | W31: 13 | X31: 5 | Y31: 5 | Z31: 2 | AA31: 2 | AB31: 4 | AC31: 3 | AD31: 1 | AE31: 2 | AF31: 9 | AG31: 3 | AH31: 2 | AI31: 7 | AJ31: 3 | AK31: 8 | AL31: 6 | AM31: 4 | AN31: 3 | AO31: 2 | AP31: 5 | AQ31: 5 | AR31: 12 | AS31: 7 | AT31: 8 | AU31: 10 | AV31: 6 | AW31: 9 | AX31: 8 | AY31: 5 | AZ31: 8 | BA31: 5 | BB31: 6 | BC31: 9 | BD31: 5 | BE31: 6
A32: 3 | B32: 9º ANO - 903 | C32: {='9º Ano - 903'!$C$17} -> 22 | D32: {='9º Ano - 903'!$C$18} -> 17 | E32: {='9º Ano - 903'!$C$19} -> 5 | F32: {='9º Ano - 903'!$C$20} -> 0 | G32: {='9º Ano - 903'!$D$70:$BB$70} -> 2 | H32: 2 | I32: 1 | J32: 1 | K32: 4 | L32: 3 | M32: 2 | N32: 4 | O32: 9 | P32: 2 | Q32: 6 | R32: 1 | S32: 3 | T32: 4 | U32: 1 | V32: 1 | W32: 9 | X32: 1 | Y32: 4 | Z32: 1 | AA32: 5 | AB32: 7 | AC32: 4 | AD32: 1 | AE32: 3 | AF32: 5 | AG32: 3 | AH32: 2 | AI32: 4 | AJ32: 5 | AK32: 4 | AL32: 2 | AM32: 5 | AN32: 7 | AO32: 1 | AP32: 1 | AQ32: 3 | AR32: 5 | AS32: 4 | AT32: 2 | AU32: 3 | AV32: 6 | AW32: 6 | AX32: 4 | AY32: 3 | AZ32: 4 | BA32: 6 | BB32: 5 | BC32: 5 | BD32: 3 | BE32: 4
A33: 4 | B33: 9º ANO - 904 | C33: {='9º Ano - 904'!$C$17} -> 27 | D33: {='9º Ano - 904'!$C$18} -> 25 | E33: {='9º Ano - 904'!$C$19} -> 2 | F33: {='9º Ano - 904'!$C$20} -> 1 | G33: {='9º Ano - 904'!$D$70:$BB$70} -> 3 | H33: 4 | I33: 2 | J33: 7 | K33: 6 | L33: 8 | M33: 4 | N33: 7 | O33: 4 | P33: 10 | Q33: 6 | R33: 4 | S33: 5 | T33: 4 | U33: 4 | V33: 2 | W33: 12 | X33: 2 | Y33: 5 | Z33: 5 | AA33: 7 | AB33: 5 | AC33: 9 | AD33: 7 | AE33: 3 | AF33: 14 | AG33: 8 | AH33: 3 | AI33: 6 | AJ33: 6 | AK33: 6 | AL33: 5 | AM33: 8 | AN33: 5 | AO33: 2 | AP33: 5 | AQ33: 8 | AR33: 6 | AS33: 5 | AT33: 4 | AU33: 9 | AV33: 6 | AW33: 6 | AX33: 3 | AY33: 7 | AZ33: 7 | BA33: 4 | BB33: 2 | BC33: 9 | BD33: 6 | BE33: 7
A34: 5
A35: 5
A36: 5
A37: 5
A38: 5
A39: 5
C40: =SUM(C30:C39) -> 110 | D40: =SUM(D30:D39) -> 93 | E40: =SUM(E30:E39) -> 17 | F40: =SUM(F30:F39) -> 1 | G40: =SUM(G30:G39) -> 12 | H40: =SUM(H30:H39) -> 18 | I40: =SUM(I30:I39) -> 6 | J40: =SUM(J30:J39) -> 15 | ... BE40: =SUM(BE30:BE39) -> 20
G42: DESEMPENHO POR HABILIDADE
G43: QUESTÃO | I43: Nº. A | J43: % | K43: HABILIDADE
G45: LINGUAGENS | H45: 1 | I45: =G40 -> 12 | J45: =SUM(I45/F$17*100) -> 10.909091 | K45: Eixo do conhecimento: Leitura. Eixo cognitivo: Analisar – Analisar a intertextualidade entre textos literários ou entre estes e outros textos verbais ou não verbais.
H46: 2 | I46: =H40 -> 18 | J46: =SUM(I46/F$17*100) -> 16.363636 | K46: Eixo do conhecimento: Leitura. Eixo cognitivo: Analisar – Analisar a intertextualidade entre textos literários ou entre estes e outros textos verbais ou não verbais.
H47: 3 | I47: =I40 -> 6 | J47: =SUM(I47/F$17*100) -> 5.4545455 | K47: Eixo do conhecimento: Leitura. Eixo cognitivo: Analisar – Analisar efeitos de sentido produzido pelo uso de formas de apropriação textual (paráfrase, citação etc.).
H48: 4 | I48: =J40 -> 15 | J48: =SUM(I48/F$17*100) -> 13.636364 | K48: Eixo do conhecimento: Língua inglesa. Eixo cognitivo: Reconhecer – Reconhecer elementos de forma e/ou conteúdo de textos de cunho artístico-cultural (artes, literatura, música, dança, festividades, entre outros) em língua inglesa
H49: 5 | I49: =K40 -> 22 | J49: =SUM(I49/F$17*100) -> 20 | K49: Eixo do conhecimento: Educação Física. Eixo cognitivo: Analisar – Diferenciar as danças urbanas, seus elementos constitutivos e seu valor cultural nas demais manifestações da dança.valor cultural nas demais manifestações da dança.
H50: 6 | I50: =L40 -> 20 | J50: =SUM(I50/F$17*100) -> 18.181818 | K50: Eixo do conhecimento: Leitura. Eixo cognitivo: Analisar – Analisar elementos constitutivos de textos pertencentes ao domínio literário.
H51: 7 | I51: =M40 -> 17 | J51: =SUM(I51/F$17*100) -> 15.454545 | K51: Eixo do conhecimento: Língua Inglesa. Eixo cognitivo: Eixo do conhecimento: Língua Inglesa. Eixo cognitivo: Analisar – Analisar a intertextualidade entre textos literários ou entre estes e outros textos verbais ou não verbais.
H52: 8 | I52: =N40 -> 17 | J52: =SUM(I52/F$17*100) -> 15.454545 | K52: Eixo do conhecimento: Leitura. Eixo cognitivo: Analisar – Analisar elementos constitutivos de textos pertencentes ao domínio literário.
H53: 9 | I53: =O40 -> 34 | J53: =SUM(I53/F$17*100) -> 30.909091 | K53: Eixo do conhecimento: Língua inglesa. Eixo cognitivo: Avaliar – Avaliar o uso do léxico (tais como palavras polissêmicas ou expressões metafóricas) em textos em língua inglesa.
H54: 10 | I54: =P40 -> 25 | J54: =SUM(I54/F$17*100) -> 22.727273 | K54: Eixo do conhecimento: Leitura. Eixo cognitivo: Analisar – Analisar elementos constitutivos de textos pertencentes ao domínio literário.
H55: 11 | I55: =Q40 -> 19 | J55: =SUM(I55/F$17*100) -> 17.272727 | K55: Eixo do conhecimento: Leitura. Eixo cognitivo: Analisar – Inferir informações implícitas em distintos textos
H56: 12 | I56: =R40 -> 11 | J56: =SUM(I56/F$17*100) -> 10 | K56: Eixo do conhecimento: Arte. Eixo cognitivo: Reconhecer – Identificar os usos de diferentes tecnologias e recursos digitais na produção e circulação das linguagens artísticas.
H57: 13 | I57: =S40 -> 16 | J57: =SUM(I57/F$17*100) -> 14.545455 | K57: Eixo do conhecimento: Leitura. Eixo cognitivo: Analisar – Inferir, em textos multissemióticos, efeitos de humor, ironia e/ou crítica.
H58: 14 | I58: =T40 -> 17 | J58: =SUM(I58/F$17*100) -> 15.454545 | K58: Eixo do conhecimento: Leitura. Eixo cognitivo: Analisar – Analisar elementos constitutivos de textos pertencentes ao domínio literário.
...

Sheet 5º Ano - 501
D6: COLEÇÃO PREPARA BRASIL
D9: ANÁLISE DE DESEMPENHO - SIMULADO 4
D12: Unidade de Ensino: 1. EMEB BENTO ELOI GARCIA
A16: 5º ANO - 501
A18: NÚMERO DE ALUNOS MATRICULADOS: | C18: =COUNTA(B30:B69) -> 29
A19: NÚMERO DE PRESENTES | C19: =SUMPRODUCT(LEN(D30:D69) - LEN(SUBSTITUTE(SUBSTITUTE(SUBSTITUTE(SUBSTITUTE(SUBSTITUTE(D30:D69,"A",""),"B",""),"C",""),"D",""),"X",""))) -> 28
A20: NÚMERO DE ALUNOS AUSENTES | C20: =COUNTIF(D30:D69,"F") -> 1
A21: NÚMERO DE ACD | C21: =COUNTIF(C30:C69,"SIM") -> 1
A23: GUIA DE CORREÇÃO - PRODUÇÃO TEXTUAL
D25: DESEMPENHO POR ITEM | BD25: NÍVEL DE PROFICIÊNCIA
A26: Nº | B26: Nome | C26: ALUNO COM DEFICIÊNCIA | D26: LINGUAGENS | Y26: MATEMÁTICA | AV26: PRODUÇÃO TEXTUAL | BD26: LINGUAGENS | BG26: MATEMÁTICA
D27: Questão 01 | E27: Questão 02 | F27: Questão 03 | G27: Questão 04 | H27: Questão 05 | I27: Questão 06 | J27: Questão 07 | K27: Questão 08 | L27: Questão 09 | M27: Questão 10 | N27: Questão 11 | O27: Questão 12 | P27: Questão 13 | Q27: Questão 14 | R27: Questão 15 | S27: Questão 16 | T27: Questão 17 | U27: Questão 18 | V27: Questão 19 | W27: Questão 20 | X27: Questão 21 | Y27: Questão 01 | Z27: Questão 02 | AA27: Questão 03 | AB27: Questão 04 | AC27: Questão 05 | AD27: Questão 06 | AE27: Questão 07 | AF27: Questão 08 | AG27: Questão 09 | AH27: Questão 10 | AI27: Questão 11 | AJ27: Questão 12 | AK27: Questão 13 | AL27: Questão 14 | AM27: Questão 15 | AN27: Questão 16 | AO27: Questão 17 | AP27: Questão 18 | AQ27: Questão 19 | AR27: Questão 20 | AS27: Questão 21 | AT27: Questão 22 | AV27: Situação | AW27: Adequação ao Gênero e ao Tema | AX27: Coerência e Coesão | AY27: Estrutura e Organização | AZ27: Ortografia e Pontuação | BA27: PONTUAÇÃO FINAL | BB27: PADRÃO DE DESEMPENHO | BD27: TCT | BE27: TRI | BF27: ESCALA DE PROFICIÊNCIA | BG27: TCT | BH27: TRI | BI27: ESCALA DE PROFICIÊNCIA
D28: 18 | E28: 9 | F28: 0 | G28: 36 | H28: 36 | I28: 36 | J28: 18 | K28: 18 | L28: 36 | M28: 36 | N28: 36 | O28: 36 | P28: 36 | Q28: 9 | R28: 18 | S28: 36 | T28: 36 | U28: 9 | V28: 0 | W28: 36 | X28: 0 | Y28: 25 | Z28: 25 | AA28: 25 | AB28: 25 | AC28: 16 | AD28: 25 | AE28: 8 | AF28: 25 | AG28: 25 | AH28: 16 | AI28: 25 | AJ28: 25 | AK28: 25 | AL28: 25 | AM28: 25 | AN28: 25 | AO28: 16 | AP28: 25 | AQ28: 25 | AR28: 25 | AS28: 25 | AT28: 25
D29: C | E29: C | F29: C | G29: B | H29: B | I29: D | J29: B | K29: B | L29: A | M29: B | N29: C | O29: C | P29: A | Q29: B | R29: D | S29: A | T29: A | U29: A | V29: C | W29: D | X29: B | Y29: A | Z29: D | AA29: C | AB29: D | AC29: C | AD29: C | AE29: B | AF29: A | AG29: D | AH29: A | AI29: C | AJ29: B | AK29: D | AL29: B | AM29: C | AN29: A | AO29: B | AP29: D | AQ29: A | AR29: C | AS29: C | AT29: B
A30: 1 | B30: ALICE DE OLIVEIRA SCHAUN | C30: NÃO | D30: C | E30: B | F30: C | G30: B | H30: A | I30: D | J30: A | K30: B | L30: B | M30: C | N30: C | O30: D | P30: A | Q30: B | R30: C | S30: A | T30: A | U30: A | V30: B | W30: C | X30: B | Y30: A | Z30: D | AA30: B | AB30: D | AC30: C | AD30: C | AE30: A | AF30: A | AG30: A | AH30: A | AI30: D | AJ30: B | AK30: D | AL30: B | AM30: C | AN30: A | AO30: B | AP30: C | AQ30: A | AR30: D | AS30: C | AT30: C | AV30: A | AW30: 3 | AX30: 2 | AY30: 2 | AZ30: 2 | BA30: =(100/16)*((SUM(AW30:AZ30))) -> 56.25 | BB30: =IF((SUM(BA30))<=25, "Abaixo do Básico", IF((SUM(BA30))<=50, "Básico", IF((SUM(BA30))<=75, "Adequado", "Avançado"))) -> Adequado | BD30: =SUMPRODUCT(--(D30:X30=D$29:X$29)) -> 12 | BE30: =SUMPRODUCT((D30:X30=D$29:X$29)*D$28:X$28) -> 270 | BF30: =IF((SUM(BE30))<=125, "Abaixo do Básico", IF((SUM(BE30))<=250, "Básico", IF((SUM(BE30))<=375, "Adequado", "Avançado"))) -> Adequado | BG30: =SUMPRODUCT(--(Y30:AT30=Y$29:AT$29)) -> 15 | BH30: =SUMPRODUCT((Y30:AT30=Y$29:AT$29)*Y$28:AT$28) -> 348 | BI30: =IF((SUM(BH30))<=125, "Abaixo do Básico", IF((SUM(BH30))<=250, "Básico", IF((SUM(BH30))<=375, "Adequado", "Avançado"))) -> Adequado
A31: 2 | B31: BERNARDO BIANCHINI ALBERTON | C31: NÃO | D31: C | E31: C | F31: C | G31: B | H31: B | I31: D | J31: B | K31: D | L31: A | M31: C | N31: C | O31: D | P31: A | Q31: B | R31: A | S31: A | T31: A | U31: A | V31: C | W31: D | X31: B | Y31: C | Z31: C | AA31: C | AB31: B | AC31: B | AD31: D | AE31: B | AF31: D | AG31: A | AH31: C | AI31: C | AJ31: D | AK31: A | AL31: B | AM31: A | AN31: A | AO31: A | AP31: A | AQ31: C | AR31: D | AS31: B | AT31: F | AV31: C | AW31: X | AX31: X | AY31: X | AZ31: X | BA31: =(100/16)*((SUM(AW31:AZ31))) -> 0 | BB31: =IF((SUM(BA31))<=25, "Abaixo do Básico", IF((SUM(BA31))<=50, "Básico", IF((SUM(BA31))<=75, "Adequado", "Avançado"))) -> Abaixo do Básico | BD31: =SUMPRODUCT(--(D31:X31=D$29:X$29)) -> 17 | BE31: =SUMPRODUCT((D31:X31=D$29:X$29)*D$28:X$28) -> 387 | BF31: =IF((SUM(BE31))<=125, "Abaixo do Básico", IF((SUM(BE31))<=250, "Básico", IF((SUM(BE31))<=375, "Adequado", "Avançado"))) -> Avançado | BG31: =SUMPRODUCT(--(Y31:AT31=Y$29:AT$29)) -> 5 | BH31: =SUMPRODUCT((Y31:AT31=Y$29:AT$29)*Y$28:AT$28) -> 108 | BI31: =IF((SUM(BH31))<=125, "Abaixo do Básico", IF((SUM(BH31))<=250, "Básico", IF((SUM(BH31))<=375, "Adequado", "Avançado"))) -> Abaixo do Básico
A32: 3 | B32: BERNARDO XAVIER OLIVEIRA DA SILVA | C32: NÃO | D32: B | E32: B | F32: C | G32: B | H32: B | I32: D | J32: B | K32: B | L32: A | M32: C | N32: C | O32: A | P32: B | Q32: B | R32: B | S32: A | T32: A | U32: A | V32: C | W32: D | X32: B | Y32: A | Z32: D | AA32: B | AB32: D | AC32: C | AD32: D | AE32: B | AF32: A | AG32: D | AH32: A | AI32: C | AJ32: B | AK32: D | AL32: B | AM32: C | AN32: D | AO32: B | AP32: C | AQ32: A | AR32: C | AS32: C | AT32: B | AV32: B | AW32: X | AX32: X | AY32: X | AZ32: X | BA32: =(100/16)*((SUM(AW32:AZ32))) -> 0 | BB32: =IF((SUM(BA32))<=25, "Abaixo do Básico", IF((SUM(BA32))<=50, "Básico", IF((SUM(BA32))<=75, "Adequado", "Avançado"))) -> Abaixo do Básico | BD32: =SUMPRODUCT(--(D32:X32=D$29:X$29)) -> 15 | BE32: =SUMPRODUCT((D32:X32=D$29:X$29)*D$28:X$28) -> 342 | BF32: =IF((SUM(BE32))<=125, "Abaixo do Básico", IF((SUM(BE32))<=250, "Básico", IF((SUM(BE32))<=375, "Adequado", "Avançado"))) -> Adequado | BG32: =SUMPRODUCT(--(Y32:AT32=Y$29:AT$29)) -> 18 | BH32: =SUMPRODUCT((Y32:AT32=Y$29:AT$29)*Y$28:AT$28) -> 406 | BI32: =IF((SUM(BH32))<=125, "Abaixo do Básico", IF((SUM(BH32))<=250, "Básico", IF((SUM(BH32))<=375, "Adequado", "Avançado"))) -> Avançado
A33: 4 | B33: BETINA ALVES MARTINS | C33: NÃO | D33: B | E33: C | F33: C | G33: B | H33: B | I33: C | J33: C | K33: B | L33: D | M33: A | N33: C | O33: D | P33: C | Q33: B | R33: B | S33: A | T33: A | U33: A | V33: C | W33: C | X33: B | Y33: A | Z33: D | AA33: B | AB33: D | AC33: C | AD33: C | AE33: B | AF33: A | AG33: D | AH33: A | AI33: D | AJ33: B | AK33: D | AL33: B | AM33: A | AN33: A | AO33: B | AP33: C | AQ33: D | AR33: C | AS33: C | AT33: A | AV33: A | AW33: 3 | AX33: 2 | AY33: 2 | AZ33: 2 | BA33: =(100/16)*((SUM(AW33:AZ33))) -> 56.25 | BB33: =IF((SUM(BA33))<=25, "Abaixo do Básico", IF((SUM(BA33))<=50, "Básico", IF((SUM(BA33))<=75, "Adequado", "Avançado"))) -> Adequado | BD33: =SUMPRODUCT(--(D33:X33=D$29:X$29)) -> 12 | BE33: =SUMPRODUCT((D33:X33=D$29:X$29)*D$28:X$28) -> 225 | BF33: =IF((SUM(BE33))<=125, "Abaixo do Básico", IF((SUM(BE33))<=250, "Básico", IF((SUM(BE33))<=375, "Adequado", "Avançado"))) -> Básico | BG33: =SUMPRODUCT(--(Y33:AT33=Y$29:AT$29)) -> 16 | BH33: =SUMPRODUCT((Y33:AT33=Y$29:AT$29)*Y$28:AT$28) -> 356 | BI33: =IF((SUM(BH33))<=125, "Abaixo do Básico", IF((SUM(BH33))<=250, "Básico", IF((SUM(BH33))<=375, "Adequado", "Avançado"))) -> Adequado
A34: 5 | B34: BRUNO DE CAMPOS GONZAGA | C34: NÃO | D34: D | E34: A | F34: A | G34: B | H34: B | I34: D | J34: D | K34: B | L34: A | M34: D | N34: C | O34: D | P34: A | Q34: B | R34: B | S34: C | T34: A | U34: A | V34: C | W34: D | X34: D | Y34: A | Z34: D | AA34: B | AB34: D | AC34: C | AD34: A | AE34: B | AF34: A | AG34: C | AH34: A | AI34: C | AJ34: B | AK34: D | AL34: B | AM34: C | AN34: C | AO34: B | AP34: C | AQ34: A | AR34: C | AS34: C | AT34: B | AV34: A | AW34: 3 | AX34: 3 | AY34: 3 | AZ34: 3 | BA34: =(100/16)*((SUM(AW34:AZ34))) -> 75 | BB34: =IF((SUM(BA34))<=25, "Abaixo do Básico", IF((SUM(BA34))<=50, "Básico", IF((SUM(BA34))<=75, "Adequado", "Avançado"))) -> Adequado | BD34: =SUMPRODUCT(--(D34:X34=D$29:X$29)) -> 12 | BE34: =SUMPRODUCT((D34:X34=D$29:X$29)*D$28:X$28) -> 324 | BF34: =IF((SUM(BE34))<=125, "Abaixo do Básico", IF((SUM(BE34))<=250, "Básico", IF((SUM(BE34))<=375, "Adequado", "Avançado"))) -> Adequado | BG34: =SUMPRODUCT(--(Y34:AT34=Y$29:AT$29)) -> 17 | BH34: =SUMPRODUCT((Y34:AT34=Y$29:AT$29)*Y$28:AT$28) -> 381 | BI34: =IF((SUM(BH34))<=125, "Abaixo do Básico", IF((SUM(BH34))<=250, "Básico", IF((SUM(BH34))<=375, "Adequado", "Avançado"))) -> Avançado
A35: 6 | B35: CRISTAL SOFIA ROYER ORTIGOZA | C35: NÃO | D35: B | E35: C | F35: D | G35: B | H35: A | I35: D | J35: B | K35: B | L35: A | M35: D | N35: C | O35: D | P35: A | Q35: B | R35: C | S35: C | T35: A | U35: A | V35: X | W35: C | X35: D | Y35: A | Z35: C | AA35: B | AB35: D | AC35: C | AD35: B | AE35: B | AF35: D | AG35: C | AH35: A | AI35: C | AJ35: B | AK35: D | AL35: B | AM35: C | AN35: A | AO35: B | AP35: C | AQ35: A | AR35: C | AS35: A | AT35: C | AV35: A | AW35: 3 | AX35: 3 | AY35: 3 | AZ35: 3 | BA35: =(100/16)*((SUM(AW35:AZ35))) -> 75 | BB35: =IF((SUM(BA35))<=25, "Abaixo do Básico", IF((SUM(BA35))<=50, "Básico", IF((SUM(BA35))<=75, "Adequado", "Avançado"))) -> Adequado | BD35: =SUMPRODUCT(--(D35:X35=D$29:X$29)) -> 11 | BE35: =SUMPRODUCT((D35:X35=D$29:X$29)*D$28:X$28) -> 279 | BF35: =IF((SUM(BE35))<=125, "Abaixo do Básico", IF((SUM(BE35))<=250, "Básico", IF((SUM(BE35))<=375, "Adequado", "Avançado"))) -> Adequado | BG35: =SUMPRODUCT(--(Y35:AT35=Y$29:AT$29)) -> 14 | BH35: =SUMPRODUCT((Y35:AT35=Y$29:AT$29)*Y$28:AT$28) -> 306 | BI35: =IF((SUM(BH35))<=125, "Abaixo do Básico", IF((SUM(BH35))<=250, "Básico", IF((SUM(BH35))<=375, "Adequado", "Avançado"))) -> Adequado
A36: 7 | B36: DANIEL MURILO CORSO | C36: NÃO | D36: D | E36: C | F36: C | G36: B | H36: D | I36: A | J36: D | K36: B | L36: C | M36: C | N36: C | O36: A | P36: B | Q36: B | R36: C | S36: A | T36: A | U36: B | V36: C | W36: D | X36: B | Y36: A | Z36: D | AA36: B | AB36: D | AC36: C | AD36: B | AE36: B | AF36: A | AG36: B | AH36: A | AI36: C | AJ36: B | AK36: B | AL36: C | AM36: A | AN36: B | AO36: A | AP36: B | AQ36: C | AR36: D | AS36: C | AT36: C | AV36: A | AW36: 3 | AX36: 3 | AY36: 3 | AZ36: 3 | BA36: =(100/16)*((SUM(AW36:AZ36))) -> 75 | BB36: =IF((SUM(BA36))<=25, "Abaixo do Básico", IF((SUM(BA36))<=50, "Básico", IF((SUM(BA36))<=75, "Adequado", "Avançado"))) -> Adequado | BD36: =SUMPRODUCT(--(D36:X36=D$29:X$29)) -> 11 | BE36: =SUMPRODUCT((D36:X36=D$29:X$29)*D$28:X$28) -> 216 | BF36: =IF((SUM(BE36))<=125, "Abaixo do Básico", IF((SUM(BE36))<=250, "Básico", IF((SUM(BE36))<=375, "Adequado", "Avançado"))) -> Básico | BG36: =SUMPRODUCT(--(Y36:AT36=Y$29:AT$29)) -> 10 | BH36: =SUMPRODUCT((Y36:AT36=Y$29:AT$29)*Y$28:AT$28) -> 215 | BI36: =IF((SUM(BH36))<=125, "Abaixo do Básico", IF((SUM(BH36))<=250, "Básico", IF((SUM(BH36))<=375, "Adequado", "Avançado"))) -> Básico
A37: 8 | B37: DAVI LUIZ AURELIANO DOS SANTOS | C37: NÃO | D37: F | E37: F | F37: F | G37: F | H37: F | I37: F | J37: F | K37: F | L37: F | M37: F | N37: F | O37: F | P37: F | Q37: F | R37: F | S37: F | T37: F | U37: F | V37: F | W37: F | X37: F | Y37: F | Z37: F | AA37: F | AB37: F | AC37: F | AD37: F | AE37: F | AF37: F | AG37: F | AH37: F | AI37: F | AJ37: F | AK37: F | AL37: F | AM37: F | AN37: F | AO37: F | AP37: F | AQ37: F | AR37: F | AS37: F | AT37: F | AV37: F | AW37: X | AX37: X | AY37: X | AZ37: X | BA37: =(100/16)*((SUM(AW37:AZ37))) -> 0 | BB37: =IF((SUM(BA37))<=25, "Abaixo do Básico", IF((SUM(BA37))<=50, "Básico", IF((SUM(BA37))<=75, "Adequado", "Avançado"))) -> Abaixo do Básico | BD37: =SUMPRODUCT(--(D37:X37=D$29:X$29)) -> 0 | BE37: =SUMPRODUCT((D37:X37=D$29:X$29)*D$28:X$28) -> 0 | BF37: =IF((SUM(BE37))<=125, "Abaixo do Básico", IF((SUM(BE37))<=250, "Básico", IF((SUM(BE37))<=375, "Adequado", "Avançado"))) -> Abaixo do Básico | BG37: =SUMPRODUCT(--(Y37:AT37=Y$29:AT$29)) -> 0 | BH37: =SUMPRODUCT((Y37:AT37=Y$29:AT$29)*Y$28:AT$28) -> 0 | BI37: =IF((SUM(BH37))<=125, "Abaixo do Básico", IF((SUM(BH37))<=250, "Básico", IF((SUM(BH37))<=375, "Adequado", "Avançado"))) -> Abaixo do Básico
A38: 9 | B38: DERMARYS DIOSAILYN MONTES DURAN | C38: NÃO | D38: D | E38: C | F38: D | G38: D | H38: A | I38: B | J38: B | K38: C | L38: A | M38: C | N38: B | O38: A | P38: A | Q38: A | R38: B | S38: A | T38: C | U38: A | V38: C | W38: D | X38: C | Y38: A | Z38: D | AA38: B | AB38: D | AC38: C | AD38: C | AE38: B | AF38: A | AG38: D | AH38: A | AI38: C | AJ38: B | AK38: D | AL38: B | AM38: C | AN38: A | AO38: B | AP38: C | AQ38: D | AR38: C | AS38: C | AT38: D | AV38: A | AW38: 3 | AX38: 3 | AY38: 3 | AZ38: 3 | BA38: =(100/16)*((SUM(AW38:AZ38))) -> 75 | BB38: =IF((SUM(BA38))<=25, "Abaixo do Básico", IF((SUM(BA38))<=50, "Básico", IF((SUM(BA38))<=75, "Adequado", "Avançado"))) -> Adequado | BD38: =SUMPRODUCT(--(D38:X38=D$29:X$29)) -> 8 | BE38: =SUMPRODUCT((D38:X38=D$29:X$29)*D$28:X$28) -> 180 | BF38: =IF((SUM(BE38))<=125, "Abaixo do Básico", IF((SUM(BE38))<=250, "Básico", IF((SUM(BE38))<=375, "Adequado", "Avançado"))) -> Básico | BG38: =SUMPRODUCT(--(Y38:AT38=Y$29:AT$29)) -> 18 | BH38: =SUMPRODUCT((Y38:AT38=Y$29:AT$29)*Y$28:AT$28) -> 406 | BI38: =IF((SUM(BH38))<=125, "Abaixo do Básico", IF((SUM(BH38))<=250, "Básico", IF((SUM(BH38))<=375, "Adequado", "Avançado"))) -> Avançado
A39: 10 | B39: ENZO MAZOTINE | C39: NÃO | D39: D | E39: B | F39: D | G39: C | H39: D | I39: D | J39: B | K39: B | L39: A | M39: B | N39: C | O39: D | P39: A | Q39: B | R39: C | S39: A | T39: A | U39: A | V39: B | W39: D | X39: D | Y39: A | Z39: D | AA39: B | AB39: D | AC39: D | AD39: C | AE39: B | AF39: B | AG39: B | AH39: A | AI39: C | AJ39: B | AK39: D | AL39: B | AM39: C | AN39: A | AO39: B | AP39: C | AQ39: D | AR39: C | AS39: C | AT39: B | AV39: A | AW39: 4 | AX39: 3 | AY39: 3 | AZ39: 3 | BA39: =(100/16)*((SUM(AW39:AZ39))) -> 81.25 | BB39: =IF((SUM(BA39))<=25, "Abaixo do Básico", IF((SUM(BA39))<=50, "Básico", IF((SUM(BA39))<=75, "Adequado", "Avançado"))) -> Avançado | BD39: =SUMPRODUCT(--(D39:X39=D$29:X$29)) -> 12 | BE39: =SUMPRODUCT((D39:X39=D$29:X$29)*D$28:X$28) -> 342 | BF39: =IF((SUM(BE39))<=125, "Abaixo do Básico", IF((SUM(BE39))<=250, "Básico", IF((SUM(BE39))<=375, "Adequado", "Avançado"))) -> Adequado | BG39: =SUMPRODUCT(--(Y39:AT39=Y$29:AT$29)) -> 16 | BH39: =SUMPRODUCT((Y39:AT39=Y$29:AT$29)*Y$28:AT$28) -> 365 | BI39: =IF((SUM(BH39))<=125, "Abaixo do Básico", IF((SUM(BH39))<=250, "Básico", IF((SUM(BH39))<=375, "Adequado", "Avançado"))) -> Adequado
A40: 11 | B40: HELOISA BOCORNI DE JESUS | C40: NÃO | D40: B | E40: B | F40: D | G40: B | H40: B | I40: D | J40: C | K40: B | L40: A | M40: C | N40: C | O40: D | P40: A | Q40: B | R40: C | S40: A | T40: A | U40: A | V40: D | W40: C | X40: B | Y40: A | Z40: D | AA40: B | AB40: D | AC40: C | AD40: C | AE40: B | AF40: A | AG40: C | AH40: D | AI40: C | AJ40: B | AK40: D | AL40: B | AM40: A | AN40: A | AO40: A | AP40: D | AQ40: A | AR40: C | AS40: C | AT40: A | AV40: A | AW40: 3 | AX40: 2 | AY40: 2 | AZ40: 2 | BA40: =(100/16)*((SUM(AW40:AZ40))) -> 56.25 | BB40: =IF((SUM(BA40))<=25, "Abaixo do Básico", IF((SUM(BA40))<=50, "Básico", IF((SUM(BA40))<=75, "Adequado", "Avançado"))) -> Adequado | BD40: =SUMPRODUCT(--(D40:X40=D$29:X$29)) -> 12 | BE40: =SUMPRODUCT((D40:X40=D$29:X$29)*D$28:X$28) -> 324 | BF40: =IF((SUM(BE40))<=125, "Abaixo do Básico", IF((SUM(BE40))<=250, "Básico", IF((SUM(BE40))<=375, "Adequado", "Avançado"))) -> Adequado | BG40: =SUMPRODUCT(--(Y40:AT40=Y$29:AT$29)) -> 16 | BH40: =SUMPRODUCT((Y40:AT40=Y$29:AT$29)*Y$28:AT$28) -> 374 | BI40: =IF((SUM(BH40))<=125, "Abaixo do Básico", IF((SUM(BH40))<=250, "Básico", IF((SUM(BH40))<=375, "Adequado", "Avançado"))) -> Adequado
A41: 12 | B41: HENZO LUIZ SYMCHAK MACHADO | C41: NÃO | D41: D | E41: B | F41: A | G41: B | H41: B | I41: A | J41: D | K41: D | L41: A | M41: D | N41: A | O41: D | P41: D | Q41: D | R41: A | S41: D | T41: D | U41: B | V41: C | W41: B | X41: D | Y41: A | Z41: A | AA41: B | AB41: D | AC41: C | AD41: C | AE41: D | AF41: A | AG41: C | AH41: D | AI41: B | AJ41: B | AK41: D | AL41: B | AM41: C | AN41: X | AO41: B | AP41: C | AQ41: D | AR41: C | AS41: C | AT41: B | AV41: A | AW41: 2 | AX41: 2 | AY41: 2 | AZ41: 2 | BA41: =(100/16)*((SUM(AW41:AZ41))) -> 50 | BB41: =IF((SUM(BA41))<=25, "Abaixo do Básico", IF((SUM(BA41))<=50, "Básico", IF((SUM(BA41))<=75, "Adequado", "Avançado"))) -> Básico | BD41: =SUMPRODUCT(--(D41:X41=D$29:X$29)) -> 4 | BE41: =SUMPRODUCT((D41:X41=D$29:X$29)*D$28:X$28) -> 108 | BF41: =IF((SUM(BE41))<=125, "Abaixo do Básico", IF((SUM(BE41))<=250, "Básico", IF((SUM(BE41))<=375, "Adequado", "Avançado"))) -> Abaixo do Básico | BG41: =SUMPRODUCT(--(Y41:AT41=Y$29:AT$29)) -> 13 | BH41: =SUMPRODUCT((Y41:AT41=Y$29:AT$29)*Y$28:AT$28) -> 307 | BI41: =IF((SUM(BH41))<=125, "Abaixo do Básico", IF((SUM(BH41))<=250, "Básico", IF((SUM(BH41))<=375, "Adequado", "Avançado"))) -> Adequado
A42: 13 | B42: IRIS BEATRIZ MARCELLO GONCALVES | C42: NÃO | D42: B | E42: B | F42: C | G42: B | H42: A | I42: D | J42: B | K42: B | L42: A | M42: D | N42: C | O42: B | P42: A | Q42: B | R42: B | S42: A | T42: C | U42: A | V42: C | W42: D | X42: B | Y42: A | Z42: D | AA42: B | AB42: D | AC42: D | AD42: C | AE42: B | AF42: A | AG42: D | AH42: A | AI42: C | AJ42: B | AK42: D | AL42: B | AM42: C | AN42: D | AO42: B | AP42: C | AQ42: D | AR42: C | AS42: C | AT42: B | AV42: C | AW42: X | AX42: X | AY42: X | AZ42: X | BA42: =(100/16)*((SUM(AW42:AZ42))) -> 0 | BB42: =IF((SUM(BA42))<=25, "Abaixo do Básico", IF((SUM(BA42))<=50, "Básico", IF((SUM(BA42))<=75, "Adequado", "Avançado"))) -> Abaixo do Básico | BD42: =SUMPRODUCT(--(D42:X42=D$29:X$29)) -> 14 | BE42: =SUMPRODUCT((D42:X42=D$29:X$29)*D$28:X$28) -> 306 | BF42: =IF((SUM(BE42))<=125, "Abaixo do Básico", IF((SUM(BE42))<=250, "Básico", IF((SUM(BE42))<=375, "Adequado", "Avançado"))) -> Adequado | BG42: =SUMPRODUCT(--(Y42:AT42=Y$29:AT$29)) -> 17 | BH42: =SUMPRODUCT((Y42:AT42=Y$29:AT$29)*Y$28:AT$28) -> 390 | BI42: =IF((SUM(BH42))<=125, "Abaixo do Básico", IF((SUM(BH42))<=250, "Básico", IF((SUM(BH42))<=375, "Adequado", "Avançado"))) -> Avançado
A43: 14 | B43: ISALELLY LIMA MARTINS | C43: NÃO | D43: C | E43: C | F43: D | G43: B | H43: D | I43: A | J43: B | K43: B | L43: A | M43: C | N43: C | O43: A | P43: A | Q43: B | R43: B | S43: B | T43: A | U43: A | V43: D | W43: D | X43: A | Y43: A | Z43: X | AA43: B | AB43: D | AC43: C | AD43: A | AE43: B | AF43: A | AG43: D | AH43: A | AI43: C | AJ43: X | AK43: X | AL43: X | AM43: C | AN43: A | AO43: B | AP43: C | AQ43: D | AR43: D | AS43: C | AT43: B | AV43: A | AW43: 4 | AX43: 3 | AY43: 3 | AZ43: 3 | BA43: =(100/16)*((SUM(AW43:AZ43))) -> 81.25 | BB43: =IF((SUM(BA43))<=25, "Abaixo do Básico", IF((SUM(BA43))<=50, "Básico", IF((SUM(BA43))<=75, "Adequado", "Avançado"))) -> Avançado | BD43: =SUMPRODUCT(--(D43:X43=D$29:X$29)) -> 12 | BE43: =SUMPRODUCT((D43:X43=D$29:X$29)*D$28:X$28) -> 297 | BF43: =IF((SUM(BE43))<=125, "Abaixo do Básico", IF((SUM(BE43))<=250, "Básico", IF((SUM(BE43))<=375, "Adequado", "Avançado"))) -> Adequado | BG43: =SUMPRODUCT(--(Y43:AT43=Y$29:AT$29)) -> 13 | BH43: =SUMPRODUCT((Y43:AT43=Y$29:AT$29)*Y$28:AT$28) -> 281 | BI43: =IF((SUM(BH43))<=125, "Abaixo do Básico", IF((SUM(BH43))<=250, "Básico", IF((SUM(BH43))<=375, "Adequado", "Avançado"))) -> Adequado
A44: 15 | B44: IZABELLA GALLEASSI BEVILAQUA | C44: NÃO | D44: C | E44: A | F44: B | G44: B | H44: D | I44: D | J44: B | K44: C | L44: A | M44: A | N44: C | O44: D | P44: A | Q44: B | R44: C | S44: A | T44: A | U44: D | V44: C | W44: D | X44: B | Y44: A | Z44: D | AA44: B | AB44: D | AC44: C | AD44: C | AE44: B | AF44: A | AG44: B | AH44: A | AI44: C | AJ44: B | AK44: D | AL44: C | AM44: A | AN44: B | AO44: B | AP44: C | AQ44: A | AR44: C | AS44: A | AT44: C | AV44: C | AW44: X | AX44: X | AY44: X | AZ44: X | BA44: =(100/16)*((SUM(AW44:AZ44))) -> 0 | BB44: =IF((SUM(BA44))<=25, "Abaixo do Básico", IF((SUM(BA44))<=50, "Básico", IF((SUM(BA44))<=75, "Adequado", "Avançado"))) -> Abaixo do Básico | BD44: =SUMPRODUCT(--(D44:X44=D$29:X$29)) -> 13 | BE44: =SUMPRODUCT((D44:X44=D$29:X$29)*D$28:X$28) -> 333 | BF44: =IF((SUM(BE44))<=125, "Abaixo do Básico", IF((SUM(BE44))<=250, "Básico", IF((SUM(BE44))<=375, "Adequado", "Avançado"))) -> Adequado | BG44: =SUMPRODUCT(--(Y44:AT44=Y$29:AT$29)) -> 14 | BH44: =SUMPRODUCT((Y44:AT44=Y$29:AT$29)*Y$28:AT$28) -> 306 | BI44: =IF((SUM(BH44))<=125, "Abaixo do Básico", IF((SUM(BH44))<=250, "Básico", IF((SUM(BH44))<=375, "Adequado", "Avançado"))) -> Adequado
A45: 16 | B45: JADSON NICOLAS ALMEIDA VALENTIM | C45: NÃO | D45: A | E45: C | F45: D | G45: D | H45: B | I45: D | J45: A | K45: C | L45: B | M45: A | N45: C | O45: D | P45: C | Q45: B | R45: B | S45: C | T45: C | U45: D | V45: B | W45: B | X45: C | Y45: A | Z45: D | AA45: B | AB45: D | AC45: C | AD45: C | AE45: A | AF45: A | AG45: D | AH45: A | AI45: C | AJ45: B | AK45: D | AL45: B | AM45: C | AN45: A | AO45: A | AP45: C | AQ45: D | AR45: D | AS45: C | AT45: B | AV45: A | AW45: 3 | AX45: 2 | AY45: 2 | AZ45: 2 | BA45: =(100/16)*((SUM(AW45:AZ45))) -> 56.25 | BB45: =IF((SUM(BA45))<=25, "Abaixo do Básico", IF((SUM(BA45))<=50, "Básico", IF((SUM(BA45))<=75, "Adequado", "Avançado"))) -> Adequado | BD45: =SUMPRODUCT(--(D45:X45=D$29:X$29)) -> 5 | BE45: =SUMPRODUCT((D45:X45=D$29:X$29)*D$28:X$28) -> 126 | BF45: =IF((SUM(BE45))<=125, "Abaixo do Básico", IF((SUM(BE45))<=250, "Básico", IF((SUM(BE45))<=375, "Adequado", "Avançado"))) -> Básico | BG45: =SUMPRODUCT(--(Y45:AT45=Y$29:AT$29)) -> 16 | BH45: =SUMPRODUCT((Y45:AT45=Y$29:AT$29)*Y$28:AT$28) -> 382 | BI45: =IF((SUM(BH45))<=125, "Abaixo do Básico", IF((SUM(BH45))<=250, "Básico", IF((SUM(BH45))<=375, "Adequado", "Avançado"))) -> Avançado
A46: 17 | B46: JHENIFFER MICKAELI MENDES DE ALBUQUERQUE | C46: NÃO | D46: C | E46: B | F46: D | G46: A | H46: B | I46: D | J46: A | K46: D | L46: A | M46: A | N46: C | O46: D | P46: D | Q46: B | R46: B | S46: A | T46: D | U46: A | V46: B | W46: B | X46: B | Y46: D | Z46: D | AA46: D | AB46: D | AC46: C | AD46: C | AE46: B | AF46: A | AG46: D | AH46: A | AI46: C | AJ46: B | AK46: D | AL46: B | AM46: A | AN46: A | AO46: B | AP46: C | AQ46: D | AR46: C | AS46: B | AT46: C | AV46: A | AW46: 3 | AX46: 3 | AY46: 3 | AZ46: 3 | BA46: =(100/16)*((SUM(AW46:AZ46))) -> 75 | BB46: =IF((SUM(BA46))<=25, "Abaixo do Básico", IF((SUM(BA46))<=50, "Básico", IF((SUM(BA46))<=75, "Adequado", "Avançado"))) -> Adequado | BD46: =SUMPRODUCT(--(D46:X46=D$29:X$29)) -> 9 | BE46: =SUMPRODUCT((D46:X46=D$29:X$29)*D$28:X$28) -> 216 | BF46: =IF((SUM(BE46))<=125, "Abaixo do Básico", IF((SUM(BE46))<=250, "Básico", IF((SUM(BE46))<=375, "Adequado", "Avançado"))) -> Básico | BG46: =SUMPRODUCT(--(Y46:AT46=Y$29:AT$29)) -> 15 | BH46: =SUMPRODUCT((Y46:AT46=Y$29:AT$29)*Y$28:AT$28) -> 331 | BI46: =IF((SUM(BH46))<=125, "Abaixo do Básico", IF((SUM(BH46))<=250, "Básico", IF((SUM(BH46))<=375, "Adequado", "Avançado"))) -> Adequado
A47: 18 | B47: JORGE D ALESSANDRO DE OLIVEIRA VILLA REAL | C47: NÃO | D47: B | E47: B | F47: C | G47: B | H47: B | I47: B | J47: B | K47: D | L47: B | M47: C | N47: C | O47: D | P47: A | Q47: B | R47: B | S47: A | T47: A | U47: A | V47: C | W47: D | X47: A | Y47: A | Z47: D | AA47: B | AB47: D | AC47: C | AD47: C | AE47: A | AF47: A | AG47: D | AH47: A | AI47: C | AJ47: B | AK47: D | AL47: B | AM47: C | AN47: A | AO47: B | AP47: C | AQ47: D | AR47: C | AS47: C | AT47: B | AV47: A | AW47: 3 | AX47: 1 | AY47: 1 | AZ47: 1 | BA47: =(100/16)*((SUM(AW47:AZ47))) -> 37.5 | BB47: =IF((SUM(BA47))<=25, "Abaixo do Básico", IF((SUM(BA47))<=50, "Básico", IF((SUM(BA47))<=75, "Adequado", "Avançado"))) -> Básico | BD47: =SUMPRODUCT(--(D47:X47=D$29:X$29)) -> 12 | BE47: =SUMPRODUCT((D47:X47=D$29:X$29)*D$28:X$28) -> 288 | BF47: =IF((SUM(BE47))<=125, "Abaixo do Básico", IF((SUM(BE47))<=250, "Básico", IF((SUM(BE47))<=375, "Adequado", "Avançado"))) -> Adequado | BG47: =SUMPRODUCT(--(Y47:AT47=Y$29:AT$29)) -> 18 | BH47: =SUMPRODUCT((Y47:AT47=Y$29:AT$29)*Y$28:AT$28) -> 423 | BI47: =IF((SUM(BH47))<=125, "Abaixo do Básico", IF((SUM(BH47))<=250, "Básico", IF((SUM(BH47))<=375, "Adequado", "Avançado"))) -> Avançado
A48: 19 | B48: JOSE ANGEL BENAVIDES LIENDO | C48: NÃO | D48: A | E48: C | F48: D | G48: B | H48: A | I48: D | J48: C | K48: D | L48: B | M48: D | N48: C | O48: C | P48: C | Q48: B | R48: C | S48: C | T48: D | U48: B | V48: B | W48: D | X48: D | Y48: A | Z48: D | AA48: B | AB48: D | AC48: C | AD48: C | AE48: A | AF48: A | AG48: D | AH48: A | AI48: C | AJ48: B | AK48: D | AL48: A | AM48: C | AN48: A | AO48: B | AP48: C | AQ48: D | AR48: C | AS48: C | AT48: B | AV48: A | AW48: 3 | AX48: 3 | AY48: 3 | AZ48: 3 | BA48: =(100/16)*((SUM(AW48:AZ48))) -> 75 | BB48: =IF((SUM(BA48))<=25, "Abaixo do Básico", IF((SUM(BA48))<=50, "Básico", IF((SUM(BA48))<=75, "Adequado", "Avançado"))) -> Adequado | BD48: =SUMPRODUCT(--(D48:X48=D$29:X$29)) -> 7 | BE48: =SUMPRODUCT((D48:X48=D$29:X$29)*D$28:X$28) -> 198 | BF48: =IF((SUM(BE48))<=125, "Abaixo do Básico", IF((SUM(BE48))<=250, "Básico", IF((SUM(BE48))<=375, "Adequado", "Avançado"))) -> Básico | BG48: =SUMPRODUCT(--(Y48:AT48=Y$29:AT$29)) -> 17 | BH48: =SUMPRODUCT((Y48:AT48=Y$29:AT$29)*Y$28:AT$28) -> 398 | BI48: =IF((SUM(BH48))<=125, "Abaixo do Básico", IF((SUM(BH48))<=250, "Básico", IF((SUM(BH48))<=375, "Adequado", "Avançado"))) -> Avançado
A49: 20 | B49: JOSUE SERPA BOZZ | C49: NÃO | D49: B | E49: C | F49: D | G49: A | H49: B | I49: A | J49: D | K49: B | L49: B | M49: A | N49: C | O49: A | P49: A | Q49: B | R49: C | S49: C | T49: A | U49: A | V49: C | W49: B | X49: B | Y49: A | Z49: D | AA49: B | AB49: D | AC49: B | AD49: C | AE49: B | AF49: A | AG49: C | AH49: A | AI49: C | AJ49: B | AK49: D | AL49: B | AM49: C | AN49: A | AO49: B | AP49: C | AQ49: B | AR49: C | AS49: B | AT49: B | AV49: A | AW49: 3 | AX49: 3 | AY49: 3 | AZ49: 3 | BA49: =(100/16)*((SUM(AW49:AZ49))) -> 75 | BB49: =IF((SUM(BA49))<=25, "Abaixo do Básico", IF((SUM(BA49))<=50, "Básico", IF((SUM(BA49))<=75, "Adequado", "Avançado"))) -> Adequado | BD49: =SUMPRODUCT(--(D49:X49=D$29:X$29)) -> 10 | BE49: =SUMPRODUCT((D49:X49=D$29:X$29)*D$28:X$28) -> 189 | BF49: =IF((SUM(BE49))<=125, "Abaixo do Básico", IF((SUM(BE49))<=250, "Básico", IF((SUM(BE49))<=375, "Adequado", "Avançado"))) -> Básico | BG49: =SUMPRODUCT(--(Y49:AT49=Y$29:AT$29)) -> 16 | BH49: =SUMPRODUCT((Y49:AT49=Y$29:AT$29)*Y$28:AT$28) -> 365 | BI49: =IF((SUM(BH49))<=125, "Abaixo do Básico", IF((SUM(BH49))<=250, "Básico", IF((SUM(BH49))<=375, "Adequado", "Avançado"))) -> Adequado
A50: 21 | B50: JUAN CARLOS FIORAVANTE PINTO | C50: NÃO | D50: D | E50: C | F50: C | G50: B | H50: A | I50: D | J50: B | K50: B | L50: B | M50: C | N50: C | O50: D | P50: C | Q50: B | R50: D | S50: B | T50: A | U50: A | V50: C | W50: D | X50: B | Y50: A | Z50: D | AA50: B | AB50: D | AC50: C | AD50: C | AE50: B | AF50: A | AG50: D | AH50: A | AI50: C | AJ50: B | AK50: D | AL50: B | AM50: C | AN50: A | AO50: B | AP50: C | AQ50: A | AR50: B | AS50: A | AT50: B | AV50: A | AW50: 2 | AX50: 2 | AY50: 2 | AZ50: 2 | BA50: =(100/16)*((SUM(AW50:AZ50))) -> 50 | BB50: =IF((SUM(BA50))<=25, "Abaixo do Básico", IF((SUM(BA50))<=50, "Básico", IF((SUM(BA50))<=75, "Adequado", "Avançado"))) -> Básico | BD50: =SUMPRODUCT(--(D50:X50=D$29:X$29)) -> 14 | BE50: =SUMPRODUCT((D50:X50=D$29:X$29)*D$28:X$28) -> 261 | BF50: =IF((SUM(BE50))<=125, "Abaixo do Básico", IF((SUM(BE50))<=250, "Básico", IF((SUM(BE50))<=375, "Adequado", "Avançado"))) -> Adequado | BG50: =SUMPRODUCT(--(Y50:AT50=Y$29:AT$29)) -> 18 | BH50: =SUMPRODUCT((Y50:AT50=Y$29:AT$29)*Y$28:AT$28) -> 406 | BI50: =IF((SUM(BH50))<=125, "Abaixo do Básico", IF((SUM(BH50))<=250, "Básico", IF((SUM(BH50))<=375, "Adequado", "Avançado"))) -> Avançado
A51: 22 | B51: KATHERINE NOAL DA SILVA | C51: NÃO | D51: B | E51: B | F51: C | G51: A | H51: A | I51: D | J51: C | K51: C | L51: B | M51: C | N51: C | O51: A | P51: D | Q51: B | R51: B | S51: A | T51: A | U51: B | V51: C | W51: D | X51: B | Y51: A | Z51: D | AA51: B | AB51: D | AC51: C | AD51: C | AE51: B | AF51: A | AG51: B | AH51: A | AI51: C | AJ51: B | AK51: D | AL51: B | AM51: C | AN51: B | AO51: B | AP51: C | AQ51: C | AR51: C | AS51: B | AT51: A | AV51: A | AW51: 3 | AX51: 3 | AY51: 3 | AZ51: 3 | BA51: =(100/16)*((SUM(AW51:AZ51))) -> 75 | BB51: =IF((SUM(BA51))<=25, "Abaixo do Básico", IF((SUM(BA51))<=50, "Básico", IF((SUM(BA51))<=75, "Adequado", "Avançado"))) -> Adequado | BD51: =SUMPRODUCT(--(D51:X51=D$29:X$29)) -> 9 | BE51: =SUMPRODUCT((D51:X51=D$29:X$29)*D$28:X$28) -> 189 | BF51: =IF((SUM(BE51))<=125, "Abaixo do Básico", IF((SUM(BE51))<=250, "Básico", IF((SUM(BE51))<=375, "Adequado", "Avançado"))) -> Básico | BG51: =SUMPRODUCT(--(Y51:AT51=Y$29:AT$29)) -> 15 | BH51: =SUMPRODUCT((Y51:AT51=Y$29:AT$29)*Y$28:AT$28) -> 331 | BI51: =IF((SUM(BH51))<=125, "Abaixo do Básico", IF((SUM(BH51))<=250, "Básico", IF((SUM(BH51))<=375, "Adequado", "Avançado"))) -> Adequado
A52: 23 | B52: LARISSA MANOELA DOS PASSOS | C52: NÃO | D52: D | E52: B | F52: C | G52: B | H52: B | I52: D | J52: B | K52: B | L52: A | M52: C | N52: C | O52: A | P52: A | Q52: B | R52: C | S52: A | T52: A | U52: A | V52: C | W52: D | X52: B | Y52: A | Z52: D | AA52: B | AB52: D | AC52: C | AD52: C | AE52: B | AF52: A | AG52: D | AH52: A | AI52: C | AJ52: B | AK52: C | AL52: B | AM52: C | AN52: D | AO52: B | AP52: C | AQ52: C | AR52: C | AS52: C | AT52: B | AV52: A | AW52: 4 | AX52: 3 | AY52: 3 | AZ52: 3 | BA52: =(100/16)*((SUM(AW52:AZ52))) -> 81.25 | BB52: =IF((SUM(BA52))<=25, "Abaixo do Básico", IF((SUM(BA52))<=50, "Básico", IF((SUM(BA52))<=75, "Adequado", "Avançado"))) -> Avançado | BD52: =SUMPRODUCT(--(D52:X52=D$29:X$29)) -> 16 | BE52: =SUMPRODUCT((D52:X52=D$29:X$29)*D$28:X$28) -> 378 | BF52: =IF((SUM(BE52))<=125, "Abaixo do Básico", IF((SUM(BE52))<=250, "Básico", IF((SUM(BE52))<=375, "Adequado", "Avançado"))) -> Avançado | BG52: =SUMPRODUCT(--(Y52:AT52=Y$29:AT$29)) -> 17 | BH52: =SUMPRODUCT((Y52:AT52=Y$29:AT$29)*Y$28:AT$28) -> 381 | BI52: =IF((SUM(BH52))<=125, "Abaixo do Básico", IF((SUM(BH52))<=250, "Básico", IF((SUM(BH52))<=375, "Adequado", "Avançado"))) -> Avançado
A53: 24 | B53: LUANE DA SILVA FERREIRA | C53: NÃO | D53: D | E53: B | F53: C | G53: B | H53: B | I53: C | J53: B | K53: B | L53: A | M53: C | N53: C | O53: D | P53: C | Q53: B | R53: B | S53: A | T53: A | U53: A | V53: C | W53: D | X53: C | Y53: A | Z53: D | AA53: C | AB53: D | AC53: A | AD53: A | AE53: D | AF53: B | AG53: B | AH53: B | AI53: C | AJ53: B | AK53: D | AL53: B | AM53: C | AN53: C | AO53: B | AP53: C | AQ53: C | AR53: B | AS53: C | AT53: A | AV53: A | AW53: 2 | AX53: 2 | AY53: 2 | AZ53: 2 | BA53: =(100/16)*((SUM(AW53:AZ53))) -> 50 | BB53: =IF((SUM(BA53))<=25, "Abaixo do Básico", IF((SUM(BA53))<=50, "Básico", IF((SUM(BA53))<=75, "Adequado", "Avançado"))) -> Básico | BD53: =SUMPRODUCT(--(D53:X53=D$29:X$29)) -> 13 | BE53: =SUMPRODUCT((D53:X53=D$29:X$29)*D$28:X$28) -> 306 | BF53: =IF((SUM(BE53))<=125, "Abaixo do Básico", IF((SUM(BE53))<=250, "Básico", IF((SUM(BE53))<=375, "Adequado", "Avançado"))) -> Adequado | BG53: =SUMPRODUCT(--(Y53:AT53=Y$29:AT$29)) -> 11 | BH53: =SUMPRODUCT((Y53:AT53=Y$29:AT$29)*Y$28:AT$28) -> 266 | BI53: =IF((SUM(BH53))<=125, "Abaixo do Básico", IF((SUM(BH53))<=250, "Básico", IF((SUM(BH53))<=375, "Adequado", "Avançado"))) -> Adequado
A54: 25 | B54: MATHEUS FELIPE BAADER | C54: NÃO | D54: C | E54: B | F54: C | G54: B | H54: D | I54: B | J54: A | K54: B | L54: A | M54: B | N54: C | O54: D | P54: A | Q54: B | R54: C | S54: C | T54: D | U54: C | V54: C | W54: D | X54: C | Y54: A | Z54: D | AA54: C | AB54: D | AC54: C | AD54: C | AE54: D | AF54: A | AG54: D | AH54: A | AI54: C | AJ54: B | AK54: D | AL54: B | AM54: C | AN54: A | AO54: A | AP54: C | AQ54: A | AR54: B | AS54: C | AT54: B | AV54: C | AW54: X | AX54: X | AY54: X | AZ54: X | BA54: =(100/16)*((SUM(AW54:AZ54))) -> 0 | BB54: =IF((SUM(BA54))<=25, "Abaixo do Básico", IF((SUM(BA54))<=50, "Básico", IF((SUM(BA54))<=75, "Adequado", "Avançado"))) -> Abaixo do Básico | BD54: =SUMPRODUCT(--(D54:X54=D$29:X$29)) -> 11 | BE54: =SUMPRODUCT((D54:X54=D$29:X$29)*D$28:X$28) -> 261 | BF54: =IF((SUM(BE54))<=125, "Abaixo do Básico", IF((SUM(BE54))<=250, "Básico", IF((SUM(BE54))<=375, "Adequado", "Avançado"))) -> Adequado | BG54: =SUMPRODUCT(--(Y54:AT54=Y$29:AT$29)) -> 18 | BH54: =SUMPRODUCT((Y54:AT54=Y$29:AT$29)*Y$28:AT$28) -> 432 | BI54: =IF((SUM(BH54))<=125, "Abaixo do Básico", IF((SUM(BH54))<=250, "Básico", IF((SUM(BH54))<=375, "Adequado", "Avançado"))) -> Avançado
A55: 26 | B55: PEDRO HENRIQUE DA CONCEICAO LOPES | C55: NÃO | D55: B | E55: A | F55: C | G55: B | H55: B | I55: D | J55: B | K55: C | L55: A | M55: C | N55: C | O55: D | P55: A | Q55: B | R55: C | S55: C | T55: A | U55: B | V55: B | W55: D | X55: B | Y55: A | Z55: D | AA55: B | AB55: D | AC55: A | AD55: B | AE55: B | AF55: D | AG55: D | AH55: A | AI55: C | AJ55: B | AK55: C | AL55: D | AM55: X | AN55: X | AO55: X | AP55: X | AQ55: X | AR55: X | AS55: X | AT55: X | AV55: C | AW55: X | AX55: X | AY55: X | AZ55: X | BA55: =(100/16)*((SUM(AW55:AZ55))) -> 0 | BB55: =IF((SUM(BA55))<=25, "Abaixo do Básico", IF((SUM(BA55))<=50, "Básico", IF((SUM(BA55))<=75, "Adequado", "Avançado"))) -> Abaixo do Básico | BD55: =SUMPRODUCT(--(D55:X55=D$29:X$29)) -> 12 | BE55: =SUMPRODUCT((D55:X55=D$29:X$29)*D$28:X$28) -> 315 | BF55: =IF((SUM(BE55))<=125, "Abaixo do Básico", IF((SUM(BE55))<=250, "Básico", IF((SUM(BE55))<=375, "Adequado", "Avançado"))) -> Adequado | BG55: =SUMPRODUCT(--(Y55:AT55=Y$29:AT$29)) -> 8 | BH55: =SUMPRODUCT((Y55:AT55=Y$29:AT$29)*Y$28:AT$28) -> 174 | BI55: =IF((SUM(BH55))<=125, "Abaixo do Básico", IF((SUM(BH55))<=250, "Básico", IF((SUM(BH55))<=375, "Adequado", "Avançado"))) -> Básico
...

Sheet 5º Ano - 502
D6: COLEÇÃO PREPARA BRASIL
D9: ANÁLISE DE DESEMPENHO - SIMULADO 4
D12: Unidade de Ensino: 1. EMEB BENTO ELOI GARCIA
A16: 5º ANO - 502
A18: NÚMERO DE ALUNOS MATRICULADOS: | C18: =COUNTA(B30:B69) -> 29
A19: NÚMERO DE PRESENTES | C19: =SUMPRODUCT(LEN(D30:D69) - LEN(SUBSTITUTE(SUBSTITUTE(SUBSTITUTE(SUBSTITUTE(SUBSTITUTE(D30:D69,"A",""),"B",""),"C",""),"D",""),"X",""))) -> 29
A20: NÚMERO DE ALUNOS AUSENTES | C20: =COUNTIF(D30:D69,"F") -> 0
A21: NÚMERO DE ACD | C21: =COUNTIF(C30:C69,"SIM") -> 1
A23: GUIA DE CORREÇÃO - PRODUÇÃO TEXTUAL
D25: DESEMPENHO POR ITEM | BD25: NÍVEL DE PROFICIÊNCIA
A26: Nº | B26: Nome | C26: ALUNO COM DEFICIÊNCIA | D26: LINGUAGENS | Y26: MATEMÁTICA | AV26: PRODUÇÃO TEXTUAL | BD26: LINGUAGENS | BG26: MATEMÁTICA
D27: Questão 01 | E27: Questão 02 | F27: Questão 03 | G27: Questão 04 | H27: Questão 05 | I27: Questão 06 | J27: Questão 07 | K27: Questão 08 | L27: Questão 09 | M27: Questão 10 | N27: Questão 11 | O27: Questão 12 | P27: Questão 13 | Q27: Questão 14 | R27: Questão 15 | S27: Questão 16 | T27: Questão 17 | U27: Questão 18 | V27: Questão 19 | W27: Questão 20 | X27: Questão 21 | Y27: Questão 01 | Z27: Questão 02 | AA27: Questão 03 | AB27: Questão 04 | AC27: Questão 05 | AD27: Questão 06 | AE27: Questão 07 | AF27: Questão 08 | AG27: Questão 09 | AH27: Questão 10 | AI27: Questão 11 | AJ27: Questão 12 | AK27: Questão 13 | AL27: Questão 14 | AM27: Questão 15 | AN27: Questão 16 | AO27: Questão 17 | AP27: Questão 18 | AQ27: Questão 19 | AR27: Questão 20 | AS27: Questão 21 | AT27: Questão 22 | AV27: Situação | AW27: Adequação ao Gênero e ao Tema | AX27: Coerência e Coesão | AY27: Estrutura e Organização | AZ27: Ortografia e Pontuação | BA27: PONTUAÇÃO FINAL | BB27: PADRÃO DE DESEMPENHO | BD27: TCT | BE27: TRI | BF27: ESCALA DE PROFICIÊNCIA | BG27: TCT | BH27: TRI | BI27: ESCALA DE PROFICIÊNCIA
D28: 18 | E28: 9 | F28: 0 | G28: 36 | H28: 36 | I28: 36 | J28: 18 | K28: 18 | L28: 36 | M28: 36 | N28: 36 | O28: 36 | P28: 36 | Q28: 9 | R28: 18 | S28: 36 | T28: 36 | U28: 9 | V28: 0 | W28: 36 | X28: 0 | Y28: 25 | Z28: 25 | AA28: 25 | AB28: 25 | AC28: 16 | AD28: 25 | AE28: 8 | AF28: 25 | AG28: 25 | AH28: 16 | AI28: 25 | AJ28: 25 | AK28: 25 | AL28: 25 | AM28: 25 | AN28: 25 | AO28: 16 | AP28: 25 | AQ28: 25 | AR28: 25 | AS28: 25 | AT28: 25
D29: C | E29: C | F29: C | G29: B | H29: B | I29: D | J29: B | K29: B | L29: A | M29: B | N29: C | O29: C | P29: A | Q29: B | R29: D | S29: A | T29: A | U29: A | V29: C | W29: D | X29: B | Y29: A | Z29: D | AA29: C | AB29: D | AC29: C | AD29: C | AE29: B | AF29: A | AG29: D | AH29: A | AI29: C | AJ29: B | AK29: D | AL29: B | AM29: C | AN29: A | AO29: B | AP29: D | AQ29: A | AR29: C | AS29: C | AT29: B
A30: 1 | B30: ALESSANDRO DE OLIVEIRA ALMEIDA | C30: NÃO | D30: A | E30: B | F30: C | G30: A | H30: B | I30: D | J30: B | K30: B | L30: A | M30: C | N30: C | O30: B | P30: A | Q30: B | R30: D | S30: A | T30: A | U30: A | V30: C | W30: D | X30: B | Y30: A | Z30: D | AA30: B | AB30: D | AC30: C | AD30: B | AE30: B | AF30: A | AG30: D | AH30: A | AI30: C | AJ30: B | AK30: D | AL30: B | AM30: C | AN30: A | AO30: B | AP30: D | AQ30: A | AR30: C | AS30: C | AT30: B | AV30: A | AW30: 3 | AX30: 3 | AY30: 3 | AZ30: 3 | BA30: =(100/16)*((SUM(AW30:AZ30))) -> 75 | BB30: =IF((SUM(BA30))<=25, "Abaixo do Básico", IF((SUM(BA30))<=50, "Básico", IF((SUM(BA30))<=75, "Adequado", "Avançado"))) -> Adequado | BD30: =SUMPRODUCT(--(D30:X30=D$29:X$29)) -> 16 | BE30: =SUMPRODUCT((D30:X30=D$29:X$29)*D$28:X$28) -> 360 | BF30: =IF((SUM(BE30))<=125, "Abaixo do Básico", IF((SUM(BE30))<=250, "Básico", IF((SUM(BE30))<=375, "Adequado", "Avançado"))) -> Adequado | BG30: =SUMPRODUCT(--(Y30:AT30=Y$29:AT$29)) -> 20 | BH30: =SUMPRODUCT((Y30:AT30=Y$29:AT$29)*Y$28:AT$28) -> 456 | BI30: =IF((SUM(BH30))<=125, "Abaixo do Básico", IF((SUM(BH30))<=250, "Básico", IF((SUM(BH30))<=375, "Adequado", "Avançado"))) -> Avançado
A31: 2 | B31: ARTHUR MONTEIRO | C31: NÃO | D31: C | E31: B | F31: D | G31: B | H31: B | I31: C | J31: A | K31: A | L31: B | M31: B | N31: A | O31: A | P31: A | Q31: B | R31: D | S31: A | T31: A | U31: A | V31: C | W31: C | X31: C | Y31: A | Z31: D | AA31: B | AB31: D | AC31: A | AD31: C | AE31: B | AF31: A | AG31: A | AH31: C | AI31: C | AJ31: B | AK31: D | AL31: B | AM31: C | AN31: A | AO31: B | AP31: D | AQ31: A | AR31: C | AS31: B | AT31: B | AV31: A | AW31: 3 | AX31: 2 | AY31: 2 | AZ31: 2 | BA31: =(100/16)*((SUM(AW31:AZ31))) -> 56.25 | BB31: =IF((SUM(BA31))<=25, "Abaixo do Básico", IF((SUM(BA31))<=50, "Básico", IF((SUM(BA31))<=75, "Adequado", "Avançado"))) -> Adequado | BD31: =SUMPRODUCT(--(D31:X31=D$29:X$29)) -> 11 | BE31: =SUMPRODUCT((D31:X31=D$29:X$29)*D$28:X$28) -> 270 | BF31: =IF((SUM(BE31))<=125, "Abaixo do Básico", IF((SUM(BE31))<=250, "Básico", IF((SUM(BE31))<=375, "Adequado", "Avançado"))) -> Adequado | BG31: =SUMPRODUCT(--(Y31:AT31=Y$29:AT$29)) -> 17 | BH31: =SUMPRODUCT((Y31:AT31=Y$29:AT$29)*Y$28:AT$28) -> 399 | BI31: =IF((SUM(BH31))<=125, "Abaixo do Básico", IF((SUM(BH31))<=250, "Básico", IF((SUM(BH31))<=375, "Adequado", "Avançado"))) -> Avançado
A32: 3 | B32: BRAYAN FELIPE STIVAN | C32: NÃO | D32: A | E32: B | F32: C | G32: B | H32: B | I32: D | J32: B | K32: B | L32: B | M32: D | N32: C | O32: B | P32: A | Q32: B | R32: D | S32: A | T32: A | U32: A | V32: C | W32: D | X32: B | Y32: A | Z32: D | AA32: B | AB32: D | AC32: C | AD32: D | AE32: B | AF32: A | AG32: B | AH32: A | AI32: C | AJ32: B | AK32: D | AL32: B | AM32: A | AN32: C | AO32: B | AP32: D | AQ32: A | AR32: C | AS32: C | AT32: B | AV32: A | AW32: 2 | AX32: 1 | AY32: 1 | AZ32: 1 | BA32: =(100/16)*((SUM(AW32:AZ32))) -> 31.25 | BB32: =IF((SUM(BA32))<=25, "Abaixo do Básico", IF((SUM(BA32))<=50, "Básico", IF((SUM(BA32))<=75, "Adequado", "Avançado"))) -> Básico | BD32: =SUMPRODUCT(--(D32:X32=D$29:X$29)) -> 16 | BE32: =SUMPRODUCT((D32:X32=D$29:X$29)*D$28:X$28) -> 360 | BF32: =IF((SUM(BE32))<=125, "Abaixo do Básico", IF((SUM(BE32))<=250, "Básico", IF((SUM(BE32))<=375, "Adequado", "Avançado"))) -> Adequado | BG32: =SUMPRODUCT(--(Y32:AT32=Y$29:AT$29)) -> 17 | BH32: =SUMPRODUCT((Y32:AT32=Y$29:AT$29)*Y$28:AT$28) -> 381 | BI32: =IF((SUM(BH32))<=125, "Abaixo do Básico", IF((SUM(BH32))<=250, "Básico", IF((SUM(BH32))<=375, "Adequado", "Avançado"))) -> Avançado
A33: 4 | B33: BRENNO ARTHUR WOSNY | C33: NÃO | D33: A | E33: B | F33: C | G33: A | H33: B | I33: A | J33: B | K33: B | L33: B | M33: A | N33: A | O33: A | P33: A | Q33: B | R33: D | S33: A | T33: A | U33: A | V33: C | W33: D | X33: B | Y33: A | Z33: D | AA33: B | AB33: D | AC33: C | AD33: B | AE33: B | AF33: A | AG33: D | AH33: A | AI33: C | AJ33: B | AK33: C | AL33: B | AM33: C | AN33: D | AO33: B | AP33: D | AQ33: A | AR33: C | AS33: C | AT33: B | AV33: A | AW33: 4 | AX33: 3 | AY33: 3 | AZ33: 3 | BA33: =(100/16)*((SUM(AW33:AZ33))) -> 81.25 | BB33: =IF((SUM(BA33))<=25, "Abaixo do Básico", IF((SUM(BA33))<=50, "Básico", IF((SUM(BA33))<=75, "Adequado", "Avançado"))) -> Avançado | BD33: =SUMPRODUCT(--(D33:X33=D$29:X$29)) -> 13 | BE33: =SUMPRODUCT((D33:X33=D$29:X$29)*D$28:X$28) -> 252 | BF33: =IF((SUM(BE33))<=125, "Abaixo do Básico", IF((SUM(BE33))<=250, "Básico", IF((SUM(BE33))<=375, "Adequado", "Avançado"))) -> Adequado | BG33: =SUMPRODUCT(--(Y33:AT33=Y$29:AT$29)) -> 18 | BH33: =SUMPRODUCT((Y33:AT33=Y$29:AT$29)*Y$28:AT$28) -> 406 | BI33: =IF((SUM(BH33))<=125, "Abaixo do Básico", IF((SUM(BH33))<=250, "Básico", IF((SUM(BH33))<=375, "Adequado", "Avançado"))) -> Avançado
A34: 5 | B34: DAVI CARDOSO SCHLEMPER | C34: NÃO | D34: D | E34: B | F34: B | G34: C | H34: B | I34: D | J34: D | K34: B | L34: A | M34: C | N34: C | O34: B | P34: A | Q34: D | R34: D | S34: A | T34: A | U34: A | V34: C | W34: D | X34: B | Y34: A | Z34: D | AA34: B | AB34: D | AC34: C | AD34: A | AE34: B | AF34: A | AG34: D | AH34: D | AI34: C | AJ34: B | AK34: D | AL34: B | AM34: C | AN34: A | AO34: B | AP34: D | AQ34: A | AR34: C | AS34: C | AT34: B | AV34: A | AW34: 3 | AX34: 3 | AY34: 3 | AZ34: 3 | BA34: =(100/16)*((SUM(AW34:AZ34))) -> 75 | BB34: =IF((SUM(BA34))<=25, "Abaixo do Básico", IF((SUM(BA34))<=50, "Básico", IF((SUM(BA34))<=75, "Adequado", "Avançado"))) -> Adequado | BD34: =SUMPRODUCT(--(D34:X34=D$29:X$29)) -> 13 | BE34: =SUMPRODUCT((D34:X34=D$29:X$29)*D$28:X$28) -> 333 | BF34: =IF((SUM(BE34))<=125, "Abaixo do Básico", IF((SUM(BE34))<=250, "Básico", IF((SUM(BE34))<=375, "Adequado", "Avançado"))) -> Adequado | BG34: =SUMPRODUCT(--(Y34:AT34=Y$29:AT$29)) -> 19 | BH34: =SUMPRODUCT((Y34:AT34=Y$29:AT$29)*Y$28:AT$28) -> 440 | BI34: =IF((SUM(BH34))<=125, "Abaixo do Básico", IF((SUM(BH34))<=250, "Básico", IF((SUM(BH34))<=375, "Adequado", "Avançado"))) -> Avançado
